<?xml version="1.0"?>
<sdf version="1.7">
  <model name="2dofPlanar">
    <!-- Manipulatator base -->
    <link name="2dofPlanarBase">
      <pose>0 0 0 0 0 0</pose>
      <visual name="2dofPlanarBaseVisual">
        <geometry>
          <cylinder>
            <radius>0.1</radius>
            <length>0.1</length>
          </cylinder>
        </geometry>
        <material>
          <ambient>1 0.4 0 1</ambient>
          <diffuse>1 0.4 0 1</diffuse>
          <specular>1 0.4 0 1</specular>
          <emissive>1 0.4 0 1</emissive>
        </material>
      </visual>
      <collision name="2dofPlanarBaseCollision">
        <pose>0 0 0 0 0 0</pose>
        <geometry>
          <cylinder>
            <radius>0.1</radius>
            <length>0.1</length>
          </cylinder>
        </geometry>
      </collision>
    </link>

    <!-- First link  -->
    <link name="2dofPlanarLink1">
      <pose>0 0 0.1 0 0 0</pose>
      <visual name="2dofPlanarLink1Visual1">
        <pose>0 0 0 0 0 0</pose>
        <geometry>
          <cylinder>
            <radius>0.1</radius>
            <length>0.1</length>
          </cylinder>
        </geometry>
        <material>
          <ambient>0.5 0.5 0.5 1</ambient>
          <diffuse>0.5 0.5 0.5 1</diffuse>
          <specular>0.5 0.5 0.5 1</specular>
          <emissive>0.5 0.5 0.5 1</emissive>
        </material>
      </visual>
      <visual name="2dofPlanarLink1Visual2">
        <pose>0 0.4 0 0 0 0</pose>
        <geometry>
          <box>
            <size>0.2 0.8 0.1</size>
          </box>
        </geometry>
        <material>
          <ambient>0.5 0.5 0.5 1</ambient>
          <diffuse>0.5 0.5 0.5 1</diffuse>
          <specular>0.5 0.5 0.5 1</specular>
          <emissive>0.5 0.5 0.5 1</emissive>
        </material>
      </visual>
      <visual name="2dofPlanarLink1Visual3">
        <pose>0 0.8 0 0 0 0</pose>
        <geometry>
          <cylinder>
            <radius>0.1</radius>
            <length>0.1</length>
          </cylinder>
        </geometry>
        <material>
          <ambient>0.5 0.5 0.5 1</ambient>
          <diffuse>0.5 0.5 0.5 1</diffuse>
          <specular>0.5 0.5 0.5 1</specular>
          <emissive>0.5 0.5 0.5 1</emissive>
        </material>
      </visual>
      <collision name="2dofPlanarLink1Collision1">
        <pose>0 0 0 0 0 0</pose>
        <geometry>
          <cylinder>
            <radius>0.1</radius>
            <length>0.1</length>
          </cylinder>
        </geometry>
      </collision>
      <collision name="2dofPlanarLink1Collision2">
        <pose>0 0.4 0 0 0 0</pose>
        <geometry>
          <box>
            <size>0.2 0.8 0.1</size>
          </box>
        </geometry>
      </collision>
      <collision name="2dofPlanarLink1Collision3">
        <pose>0 0.8 0 0 0 0</pose>
        <geometry>
          <cylinder>
            <radius>0.1</radius>
            <length>0.1</length>
          </cylinder>
        </geometry>
      </collision>
    </link>

    <!-- First joint  -->
    <joint name="2dofPlanarJoint1" type="revolute">
      <parent>2dofPlanarBase</parent>
      <child>2dofPlanarLink1</child>
      <axis>
        <xyz>0 0 1</xyz>
        <limit>
          <lower>-3.14159</lower>
          <upper>3.14159</upper>
        </limit>
      </axis>
    </joint>

    <!-- Second link  -->
    <link name="2dofPlanarLink2">
      <pose>0 0.8 0.2 0 0 0</pose>
      <visual name="2dofPlanarLink2Visual1">
        <pose>0 0 0 0 0 0</pose>
        <geometry>
          <cylinder>
            <radius>0.1</radius>
            <length>0.1</length>
          </cylinder>
        </geometry>
        <material>
          <ambient>1 0.4 0 1</ambient>
          <diffuse>1 0.4 0 1</diffuse>
          <specular>1 0.4 0 1</specular>
          <emissive>1 0.4 0 1</emissive>
        </material>
      </visual>
      <visual name="2dofPlanarLink2Visual2">
        <pose>0 0.4 0 0 0 0</pose>
        <geometry>
          <box>
            <size>0.2 0.8 0.1</size>
          </box>
        </geometry>
        <material>
          <ambient>1 0.4 0 1</ambient>
          <diffuse>1 0.4 0 1</diffuse>
          <specular>1 0.4 0 1</specular>
          <emissive>1 0.4 0 1</emissive>
        </material>
      </visual>
      <visual name="2dofPlanarLink2Visual3">
        <pose>0 0.8 0 0 0 0</pose>
        <geometry>
          <cylinder>
            <radius>0.1</radius>
            <length>0.1</length>
          </cylinder>
        </geometry>
        <material>
          <ambient>1 0.4 0 1</ambient>
          <diffuse>1 0.4 0 1</diffuse>
          <specular>1 0.4 0 1</specular>
          <emissive>1 0.4 0 1</emissive>
        </material>
      </visual>
      <collision name="2dofPlanarLink2Collision1">
        <pose>0 0 0 0 0 0</pose>
        <geometry>
          <cylinder>
            <radius>0.1</radius>
            <length>0.1</length>
          </cylinder>
        </geometry>
      </collision>
      <collision name="2dofPlanarLink2Collision2">
        <pose>0 0.4 0 0 0 0</pose>
        <geometry>
          <box>
            <size>0.2 0.8 0.1</size>
          </box>
        </geometry>
      </collision>
      <collision name="2dofPlanarLink2Collision3">
        <pose>0 0.8 0 0 0 0</pose>
        <geometry>
          <cylinder>
            <radius>0.1</radius>
            <length>0.1</length>
          </cylinder>
        </geometry>
      </collision>
    </link>

    <!-- Second joint  -->
    <joint name="2dofPlanarJoint2" type="revolute">
      <parent>2dofPlanarLink1</parent>
      <child>2dofPlanarLink2</child>
      <axis>
        <xyz>0 0 1</xyz>
        <limit>
          <lower>-3.14159</lower>
          <upper>3.14159</upper>
        </limit>
      </axis>
    </joint>

    <!-- Manipulatator end effector -->
    <link name="2dofPlanarEndEffector">
      <pose>0 1.6 0.2 0 0 0</pose>
    </link>

    <!-- End effector joint  -->
    <joint name="2dofPlanarJointEndEffector" type="fixed">
      <parent>2dofPlanarLink2</parent>
      <child>2dofPlanarEndEffector</child>
    </joint>
  </model>
</sdf>
